Workbook

Sheet STOCK
A1: SL NO | B1: WAREHOUSE | C1: MATERIAL | D1: DISCRIPTION | E1: 46092
A2: 1 | B2: JAIPUR | C2: ANTENNA | D2: B6-DISH ANTENNA
A3: 2 | B3: JAIPUR | C3: ANTENNA | D3: A6 RADIO ODU | E3: 2
A4: 3 | B4: JAIPUR | C4: ANTENNA | D4: B6 RADIO ODU
A5: 4 | B5: JAIPUR | C5: CABLE | D5: B6-LOGIN CABLE
A6: 5 | B6: JAIPUR | C6: CABLE | D6: CBL ELEC N-ARM 1.1KV AL PVC 1C 10 SQ.MM.
A7: 6 | B7: JAIPUR | C7: CABLE CAT-6 | D7: B6-CABLE CAT-6 UTP (B6-LOGIN CABLE)
A8: 7 | B8: JAIPUR | C8: CABLE CAT-6 | D8: B6-CABLE CAT-6 UTP (B6-LOGIN CABLE-50 MTR)
A9: 8 | B9: JAIPUR | C9: CABLE CAT-6 | D9: B6-CABLE CAT-6 UTP (B6-LOGIN CABLE-60 MTR)
A10: 9 | B10: JAIPUR | C10: CABLE CPRI | D10: B6-CPRI CABLE 50 MTR - (MULTIMODE)
A11: 10 | B11: JAIPUR | C11: CABLE CPRI | D11: B6-CPRI CABLE 60 MTR - (MULTIMODE)
A12: 11 | B12: JAIPUR | C12: CABLE CPRI | D12: CPRI CABLE 05 MTR - (MULTIMODE) | E12: 3
A13: 12 | B13: JAIPUR | C13: CABLE CPRI | D13: CPRI CABLE 30 MTR - (MULTIMODE)
A14: 13 | B14: JAIPUR | C14: CABLE CPRI | D14: CPRI CABLE 40 MTR - (MULTIMODE) | E14: 1
A15: 14 | B15: JAIPUR | C15: CABLE CPRI | D15: CPRI CABLE 70 MTR - (MULTIMODE)
A16: 15 | B16: JAIPUR | C16: CABLE CPRI | D16: FIBER,LC DUP PC-LC DUP APC,SM,3MTR
A17: 16 | B17: JAIPUR | C17: CABLE EARTHING | D17: EARTHING CABLE
A18: 17 | B18: JAIPUR | C18: CABLE POWER | D18: POWER CABLE 30 MTR (MULTIMODE)
A19: 18 | B19: JAIPUR | C19: CABLE POWER | D19: POWER CABLE 40 MTR (MULTIMODE)
A20: 19 | B20: JAIPUR | C20: CABLE POWER | D20: POWER CABLE 50 MTR (MULTIMODE) | E20: 2
A21: 20 | B21: JAIPUR | C21: CABLE POWER | D21: POWER CABLE 60 MTR (MULTIMODE) | E21: 0
A22: 21 | B22: JAIPUR | C22: CABLE POWER | D22: POWER CABLE 70 MTR (MULTIMODE)
A23: 22 | B23: JAIPUR | C23: CLAMP | D23: EARTHING CLAMP
A24: 23 | B24: JAIPUR | C24: CLAMP | D24: GRIPPING CLAMP-STUB
A25: 24 | B25: JAIPUR | C25: GLAND | D25: GLAND FREED FROM CPRI
A26: 25 | B26: JAIPUR | C26: IRM KIT | D26: B6-INSTALLATION IRM KIT
A27: 26 | B27: JAIPUR | C27: IRM KIT | D27: A6 INSTALLATION IRM KIT | E27: 2
A28: 27 | B28: JAIPUR | C28: MOUNT BRACKET | D28: B6-MOUNTING BRACKET
A29: 28 | B29: JAIPUR | C29: MOUNT BRACKET | D29: A6 MOUNTING BRACKET | E29: 2
A30: 29 | B30: JAIPUR | C30: POLE MOUNT | D30: A6 GBM POLE MOUNT 1.6M | E30: 3
A31: 30 | B31: JAIPUR | C31: SFP | D31: SFP 10 G/S OPTICAL ETHERNET 10G BASE SR MM
A32: 31 | B32: JAIPUR | C32: SFP | D32: SFP MULTIMODE 10G - AIR FIBER | E32: 4
A33: 32 | B33: JAIPUR | C33: SFP | D33: SFP MULTIMODE 1G - AIR FIBER
A34: 33 | B34: JAIPUR | C34: ADAPTOR | D34: V1 TO V2 ADAPTER POWER CABLE
A35: 34 | B35: JAIPUR | C35: ANTENNA | D35: ANTENNA 850 | E35: 0
A36: 35 | B36: JAIPUR | C36: ANTENNA | D36: ANTENNA PENTABAND | E36: 0
A37: 36 | B37: JAIPUR | C37: ANTENNA | D37: BI SECTOR ANTENNA - 2300 MHZ | E37: 0
A38: 37 | B38: JAIPUR | C38: ANTENNA | D38: MB ANTENNA PACKING BOX | E38: 0
A39: 38 | B39: JAIPUR | C39: ANTENNA | D39: MB ANTENNA PACKING FOAM
A40: 39 | B40: JAIPUR | C40: CABLE | D40: CBL ELEC N-ARM 1.1KV BARECOPPER PVC 1C 6
...

Sheet JIO MIN
A1: JIO MIN
A2: SL NO | B2: WAREHOUSE | C2: MATERIAL | D2: DISCRIPTION | E2: 46093
A3: 1 | B3: JAIPUR | C3: ANTENNA | D3: B6-DISH ANTENNA | E3: 2
A4: 2 | B4: JAIPUR | C4: ANTENNA | D4: A6 RADIO ODU | E4: 8
A5: 3 | B5: JAIPUR | C5: ANTENNA | D5: B6 RADIO ODU | E5: 2
A6: 4 | B6: JAIPUR | C6: CABLE | D6: B6-LOGIN CABLE
A7: 5 | B7: JAIPUR | C7: CABLE | D7: CBL ELEC N-ARM 1.1KV AL PVC 1C 10 SQ.MM. | E7: 20
A8: 6 | B8: JAIPUR | C8: CABLE CAT-6 | D8: B6-CABLE CAT-6 UTP (B6-LOGIN CABLE 40 MTR)
A9: 7 | B9: JAIPUR | C9: CABLE CAT-6 | D9: B6-CABLE CAT-6 UTP (B6-LOGIN CABLE-50 MTR) | E9: 2
A10: 8 | B10: JAIPUR | C10: CABLE CAT-6 | D10: B6-CABLE CAT-6 UTP (B6-LOGIN CABLE-60 MTR)
A11: 9 | B11: JAIPUR | C11: CABLE CPRI | D11: B6-CPRI CABLE 50 MTR - (MULTIMODE) | E11: 1
A12: 10 | B12: JAIPUR | C12: CABLE CPRI | D12: B6-CPRI CABLE 60 MTR - (MULTIMODE)
A13: 11 | B13: JAIPUR | C13: CABLE CPRI | D13: CPRI CABLE 05 MTR - (MULTIMODE) | E13: 8
A14: 12 | B14: JAIPUR | C14: CABLE CPRI | D14: CPRI CABLE 30 MTR - (MULTIMODE)
A15: 13 | B15: JAIPUR | C15: CABLE CPRI | D15: CPRI CABLE 40 MTR - (MULTIMODE)
A16: 14 | B16: JAIPUR | C16: CABLE CPRI | D16: CPRI CABLE 70 MTR - (MULTIMODE)
A17: 15 | B17: JAIPUR | C17: CABLE CPRI | D17: FIBER,LC DUP PC-LC DUP APC,SM,3MTR
A18: 16 | B18: JAIPUR | C18: CABLE EARTHING | D18: B6 EARTHING CABLE
A19: 17 | B19: JAIPUR | C19: CABLE POWER | D19: POWER CABLE 30 MTR (MULTIMODE)
A20: 18 | B20: JAIPUR | C20: CABLE POWER | D20: POWER CABLE 40 MTR (MULTIMODE)
A21: 19 | B21: JAIPUR | C21: CABLE POWER | D21: POWER CABLE 50 MTR (MULTIMODE) | E21: 7
A22: 20 | B22: JAIPUR | C22: CABLE POWER | D22: POWER CABLE 60 MTR (MULTIMODE) | E22: 3
A23: 21 | B23: JAIPUR | C23: CABLE POWER | D23: POWER CABLE 70 MTR (MULTIMODE)
A24: 22 | B24: JAIPUR | C24: CLAMP | D24: EARTHING CLAMP | E24: 1
A25: 23 | B25: JAIPUR | C25: CLAMP | D25: GRIPPING CLAMP-STUB
A26: 24 | B26: JAIPUR | C26: GLAND | D26: GLAND FREED FROM CPRI
A27: 25 | B27: JAIPUR | C27: IRM KIT | D27: B6-INSTALLATION IRM KIT | E27: 2
A28: 26 | B28: JAIPUR | C28: IRM KIT | D28: A6 INSTALLATION IRM KIT | E28: 8
A29: 27 | B29: JAIPUR | C29: MOUNT BRACKET | D29: B6-MOUNTING BRACKET | E29: 2
A30: 28 | B30: JAIPUR | C30: MOUNT BRACKET | D30: A6 MOUNTING BRACKET | E30: 8
A31: 29 | B31: JAIPUR | C31: POLE MOUNT | D31: A6 GBM POLE MOUNT 1.6M
A32: 30 | B32: JAIPUR | C32: SFP | D32: SFP 10 G/S OPTICAL ETHERNET 10G BASE SR MM
A33: 31 | B33: JAIPUR | C33: SFP | D33: SFP MULTIMODE 10G - AIR FIBER | E33: 18
A34: 32 | B34: JAIPUR | C34: SFP | D34: SFP MULTIMODE 1G - AIR FIBER
A35: 33 | B35: JAIPUR | C35: ADAPTOR | D35: V1 TO V2 ADAPTER POWER CABLE
A36: 34 | B36: JAIPUR | C36: ANTENNA | D36: ANTENNA 850
A37: 35 | B37: JAIPUR | C37: ANTENNA | D37: ANTENNA PENTABAND | E37: 8
A38: 36 | B38: JAIPUR | C38: ANTENNA | D38: BI SECTOR ANTENNA - 2300 MHZ
A39: 37 | B39: JAIPUR | C39: ANTENNA | D39: MB ANTENNA PACKING BOX | E39: 15
A40: 38 | B40: JAIPUR | C40: ANTENNA | D40: MB ANTENNA PACKING FOAM | E40: 2
...

Sheet JIO MRN
A1: JIO MRN
A2: SL NO | B2: WAREHOUSE | C2: MATERIAL | D2: DISCRIPTION | E2: 46093
A3: 1 | B3: JAIPUR | C3: ANTENNA | D3: B6-DISH ANTENNA
A4: 2 | B4: JAIPUR | C4: ANTENNA | D4: A6 RADIO ODU
A5: 3 | B5: JAIPUR | C5: ANTENNA | D5: B6 RADIO ODU
A6: 4 | B6: JAIPUR | C6: CABLE | D6: B6-LOGIN CABLE
A7: 5 | B7: JAIPUR | C7: CABLE | D7: CBL ELEC N-ARM 1.1KV AL PVC 1C 10 SQ.MM.
A8: 6 | B8: JAIPUR | C8: CABLE CAT-6 | D8: B6-CABLE CAT-6 UTP (B6-LOGIN CABLE)
A9: 7 | B9: JAIPUR | C9: CABLE CAT-6 | D9: B6-CABLE CAT-6 UTP (B6-LOGIN CABLE-50 MTR)
A10: 8 | B10: JAIPUR | C10: CABLE CAT-6 | D10: B6-CABLE CAT-6 UTP (B6-LOGIN CABLE-60 MTR)
A11: 9 | B11: JAIPUR | C11: CABLE CPRI | D11: B6-CPRI CABLE 50 MTR - (MULTIMODE)
A12: 10 | B12: JAIPUR | C12: CABLE CPRI | D12: B6-CPRI CABLE 60 MTR - (MULTIMODE)
A13: 11 | B13: JAIPUR | C13: CABLE CPRI | D13: CPRI CABLE 05 MTR - (MULTIMODE)
A14: 12 | B14: JAIPUR | C14: CABLE CPRI | D14: CPRI CABLE 30 MTR - (MULTIMODE)
... A235: 10 | B235: LUCKNOW | C235: MM WAVE | D235: A6 GBM POLE MOUNT 1.6M

Sheet TEAM OUT
A1: TEAM MATERIAL OUT DATE
A2: SL NO | B2: WAREHOUSE | C2: MATERIAL | D2: DISCRIPTION | E2: 46093
A3: 1 | B3: JAIPUR | C3: ANTENNA | D3: B6-DISH ANTENNA
A4: 2 | B4: JAIPUR | C4: ANTENNA | D4: A6 RADIO ODU
A5: 3 | B5: JAIPUR | C5: ANTENNA | D5: B6 RADIO ODU
A6: 4 | B6: JAIPUR | C6: CABLE | D6: B6-LOGIN CABLE
A7: 5 | B7: JAIPUR | C7: CABLE | D7: CBL ELEC N-ARM 1.1KV AL PVC 1C 10 SQ.MM.
A8: 6 | B8: JAIPUR | C8: CABLE CAT-6 | D8: B6-CABLE CAT-6 UTP (B6-LOGIN CABLE)
A9: 7 | B9: JAIPUR | C9: CABLE CAT-6 | D9: B6-CABLE CAT-6 UTP (B6-LOGIN CABLE-50 MTR)
A10: 8 | B10: JAIPUR | C10: CABLE CAT-6 | D10: B6-CABLE CAT-6 UTP (B6-LOGIN CABLE-60 MTR)
A11: 9 | B11: JAIPUR | C11: CABLE CPRI | D11: B6-CPRI CABLE 50 MTR - (MULTIMODE)
A12: 10 | B12: JAIPUR | C12: CABLE CPRI | D12: B6-CPRI CABLE 60 MTR - (MULTIMODE)
A13: 11 | B13: JAIPUR | C13: CABLE CPRI | D13: CPRI CABLE 05 MTR - (MULTIMODE)
A14: 12 | B14: JAIPUR | C14: CABLE CPRI | D14: CPRI CABLE 30 MTR - (MULTIMODE)
... A235: 10 | B235: LUCKNOW | C235: MM WAVE | D235: A6 GBM POLE MOUNT 1.6M

Sheet TEAM IN
A1: TEAM MATERIAL IN DATE
A2: SL NO | B2: WAREHOUSE | C2: MATERIAL | D2: DISCRIPTION | E2: 46093
A3: 1 | B3: JAIPUR | C3: ANTENNA | D3: B6-DISH ANTENNA
A4: 2 | B4: JAIPUR | C4: ANTENNA | D4: A6 RADIO ODU
A5: 3 | B5: JAIPUR | C5: ANTENNA | D5: B6 RADIO ODU
A6: 4 | B6: JAIPUR | C6: CABLE | D6: B6-LOGIN CABLE
A7: 5 | B7: JAIPUR | C7: CABLE | D7: CBL ELEC N-ARM 1.1KV AL PVC 1C 10 SQ.MM.
A8: 6 | B8: JAIPUR | C8: CABLE CAT-6 | D8: B6-CABLE CAT-6 UTP (B6-LOGIN CABLE)
A9: 7 | B9: JAIPUR | C9: CABLE CAT-6 | D9: B6-CABLE CAT-6 UTP (B6-LOGIN CABLE-50 MTR)
A10: 8 | B10: JAIPUR | C10: CABLE CAT-6 | D10: B6-CABLE CAT-6 UTP (B6-LOGIN CABLE-60 MTR)
A11: 9 | B11: JAIPUR | C11: CABLE CPRI | D11: B6-CPRI CABLE 50 MTR - (MULTIMODE)
A12: 10 | B12: JAIPUR | C12: CABLE CPRI | D12: B6-CPRI CABLE 60 MTR - (MULTIMODE)
A13: 11 | B13: JAIPUR | C13: CABLE CPRI | D13: CPRI CABLE 05 MTR - (MULTIMODE)
A14: 12 | B14: JAIPUR | C14: CABLE CPRI | D14: CPRI CABLE 30 MTR - (MULTIMODE)
... A145: 1 | B145: LUCKNOW | C145: ANTENNA | D145: B6-DISH ANTENNA
A146: 2 | B146: LUCKNOW | C146: ANTENNA | D146: A6 RADIO ODU | E146: 1
A147: 3 | B147: LUCKNOW | C147: ANTENNA | D147: B6 RADIO ODU
A148: 4 | B148: LUCKNOW | C148: CABLE | D148: B6-LOGIN CABLE
A149: 5 | B149: LUCKNOW | C149: CABLE | D149: CBL ELEC N-ARM 1.1KV AL PVC 1C 10 SQ.MM.
A150: 6 | B150: LUCKNOW | C150: CABLE CAT-6 | D150: B6-CABLE CAT-6 UTP (B6-LOGIN CABLE)
A151: 7 | B151: LUCKNOW | C151: CABLE CAT-6 | D151: B6-CABLE CAT-6 UTP (B6-LOGIN CABLE-50 MTR)
A152: 8 | B152: LUCKNOW | C152: CABLE CAT-6 | D152: B6-CABLE CAT-6 UTP (B6-LOGIN CABLE-60 MTR)
A153: 9 | B153: LUCKNOW | C153: CABLE CPRI | D153: B6-CPRI CABLE 50 MTR - (MULTIMODE)
A154: 10 | B154: LUCKNOW | C154: CABLE CPRI | D154: B6-CPRI CABLE 60 MTR - (MULTIMODE)
A155: 11 | B155: LUCKNOW | C155: CABLE CPRI | D155: CPRI CABLE 05 MTR - (MULTIMODE)
A156: 12 | B156: LUCKNOW | C156: CABLE CPRI | D156: CPRI CABLE 30 MTR - (MULTIMODE)
A157: 13 | B157: LUCKNOW | C157: CABLE CPRI | D157: CPRI CABLE 40 MTR - (MULTIMODE)
A158: 14 | B158: LUCKNOW | C158: CABLE CPRI | D158: CPRI CABLE 70 MTR - (MULTIMODE)
... A162: 18 | B162: LUCKNOW | C162: CABLE POWER | D162: POWER CABLE 40 MTR (MULTIMODE)
A163: 19 | B163: LUCKNOW | C163: CABLE POWER | D163: POWER CABLE 50 MTR (MULTIMODE) | E163: 1
A164: 20 | B164: LUCKNOW | C164: CABLE POWER | D164: POWER CABLE 60 MTR (MULTIMODE)
A165: 21 | B165: LUCKNOW | C165: CABLE POWER | D165: POWER CABLE 70 MTR (MULTIMODE)
A166: 22 | B166: LUCKNOW | C166: CLAMP | D166: EARTHING CLAMP
A167: 23 | B167: LUCKNOW | C167: CLAMP | D167: GRIPPING CLAMP-STUB
A168: 24 | B168: LUCKNOW | C168: GLAND | D168: GLAND FREED FROM CPRI
A169: 25 | B169: LUCKNOW | C169: IRM KIT | D169: B6-INSTALLATION IRM KIT
A170: 26 | B170: LUCKNOW | C170: IRM KIT | D170: A6 INSTALLATION IRM KIT | E170: 1
A171: 27 | B171: LUCKNOW | C171: MOUNT BRACKET | D171: B6-MOUNTING BRACKET
A172: 28 | B172: LUCKNOW | C172: MOUNT BRACKET | D172: A6 MOUNTING BRACKET | E172: 1
A173: 29 | B173: LUCKNOW | C173: POLE MOUNT | D173: A6 GBM POLE MOUNT 1.6M
...

Sheet SUMMARY
A1: SL NO | B1: WAREHOUSE NAME | C1: MATERIAL NAME | D1: REMARKS | E1: QTY | F1: 46092 | K1: NEXT DAY STOCK 11-Mar-26 | L1: DIFFERENCE
F2: WAREHOUSE | H2: FIELD | J2: F QTY
F3: MIN + | G3: MRN - | H3: TEAM OUT - | I3: TEAM IN +
A4: 1 | B4: JAIPUR | C4: ANTENNA | D4: B6-DISH ANTENNA | E4: =STOCK!E2 -> 0 | F4: ='JIO MIN'!E3 -> 2 | G4: ='JIO MRN'!E3 -> 0 | H4: ='TEAM OUT'!E3 -> 0 | I4: ='TEAM IN'!E3 -> 0 | J4: =E4+F4-G4-H4+I4 -> 2 | K4: 2 | L4: =J4-K4 -> 0
A5: 2 | B5: JAIPUR | C5: ANTENNA | D5: A6 RADIO ODU | E5: =STOCK!E3 -> 2 | F5: ='JIO MIN'!E4 -> 8 | G5: ='JIO MRN'!E4 -> 0 | H5: ='TEAM OUT'!E4 -> 0 | I5: ='TEAM IN'!E4 -> 0 | J5: =E5+F5-G5-H5+I5 -> 10 | K5: 10 | L5: =J5-K5 -> 0
A6: 3 | B6: JAIPUR | C6: ANTENNA | D6: B6 RADIO ODU | E6: =STOCK!E4 -> 0 | F6: ='JIO MIN'!E5 -> 2 | G6: ='JIO MRN'!E5 -> 0 | H6: ='TEAM OUT'!E5 -> 0 | I6: ='TEAM IN'!E5 -> 0 | J6: =E6+F6-G6-H6+I6 -> 2 | K6: 2 | L6: =J6-K6 -> 0
A7: 4 | B7: JAIPUR | C7: CABLE | D7: B6-LOGIN CABLE | E7: =STOCK!E5 -> 0 | F7: ='JIO MIN'!E6 -> 0 | G7: ='JIO MRN'!E6 -> 0 | H7: ='TEAM OUT'!E6 -> 0 | I7: ='TEAM IN'!E6 -> 0 | J7: =E7+F7-G7-H7+I7 -> 0 | L7: =J7-K7 -> 0
A8: 5 | B8: JAIPUR | C8: CABLE | D8: CBL ELEC N-ARM 1.1KV AL PVC 1C 10 SQ.MM. | E8: =STOCK!E6 -> 0 | F8: ='JIO MIN'!E7 -> 20 | G8: ='JIO MRN'!E7 -> 0 | H8: ='TEAM OUT'!E7 -> 0 | I8: ='TEAM IN'!E7 -> 0 | J8: =E8+F8-G8-H8+I8 -> 20 | K8: 20 | L8: =J8-K8 -> 0
A9: 6 | B9: JAIPUR | C9: CABLE CAT-6 | D9: B6-CABLE CAT-6 UTP (B6-LOGIN CABLE) | E9: =STOCK!E7 -> 0 | F9: ='JIO MIN'!E8 -> 0 | G9: ='JIO MRN'!E8 -> 0 | H9: ='TEAM OUT'!E8 -> 0 | I9: ='TEAM IN'!E8 -> 0 | J9: =E9+F9-G9-H9+I9 -> 0 | L9: =J9-K9 -> 0
A10: 7 | B10: JAIPUR | C10: CABLE CAT-6 | D10: B6-CABLE CAT-6 UTP (B6-LOGIN CABLE-50 MTR) | E10: =STOCK!E8 -> 0 | F10: ='JIO MIN'!E9 -> 2 | G10: ='JIO MRN'!E9 -> 0 | H10: ='TEAM OUT'!E9 -> 0 | I10: ='TEAM IN'!E9 -> 0 | J10: =E10+F10-G10-H10+I10 -> 2 | K10: 2 | L10: =J10-K10 -> 0
A11: 8 | B11: JAIPUR | C11: CABLE CAT-6 | D11: B6-CABLE CAT-6 UTP (B6-LOGIN CABLE-60 MTR) | E11: =STOCK!E9 -> 0 | F11: ='JIO MIN'!E10 -> 0 | G11: ='JIO MRN'!E10 -> 0 | H11: ='TEAM OUT'!E10 -> 0 | I11: ='TEAM IN'!E10 -> 0 | J11: =E11+F11-G11-H11+I11 -> 0 | L11: =J11-K11 -> 0
A12: 9 | B12: JAIPUR | C12: CABLE CPRI | D12: B6-CPRI CABLE 50 MTR - (MULTIMODE) | E12: =STOCK!E10 -> 0 | F12: ='JIO MIN'!E11 -> 1 | G12: ='JIO MRN'!E11 -> 0 | H12: ='TEAM OUT'!E11 -> 0 | I12: ='TEAM IN'!E11 -> 0 | J12: =E12+F12-G12-H12+I12 -> 1 | K12: 1 | L12: =J12-K12 -> 0
A13: 10 | B13: JAIPUR | C13: CABLE CPRI | D13: B6-CPRI CABLE 60 MTR - (MULTIMODE) | E13: =STOCK!E11 -> 0 | F13: ='JIO MIN'!E12 -> 0 | G13: ='JIO MRN'!E12 -> 0 | H13: ='TEAM OUT'!E12 -> 0 | I13: ='TEAM IN'!E12 -> 0 | J13: =E13+F13-G13-H13+I13 -> 0 | L13: =J13-K13 -> 0
A14: 11 | B14: JAIPUR | C14: CABLE CPRI | D14: CPRI CABLE 05 MTR - (MULTIMODE) | E14: =STOCK!E12 -> 3 | F14: ='JIO MIN'!E13 -> 8 | G14: ='JIO MRN'!E13 -> 0 | H14: ='TEAM OUT'!E13 -> 0 | I14: ='TEAM IN'!E13 -> 0 | J14: =E14+F14-G14-H14+I14 -> 11 | K14: 11 | L14: =J14-K14 -> 0
A15: 12 | B15: JAIPUR | C15: CABLE CPRI | D15: CPRI CABLE 30 MTR - (MULTIMODE) | E15: =STOCK!E13 -> 0 | F15: ='JIO MIN'!E14 -> 0 | G15: ='JIO MRN'!E14 -> 0 | H15: ='TEAM OUT'!E14 -> 0 | I15: ='TEAM IN'!E14 -> 0 | J15: =E15+F15-G15-H15+I15 -> 0 | L15: =J15-K15 -> 0
A16: 13 | B16: JAIPUR | C16: CABLE CPRI | D16: CPRI CABLE 40 MTR - (MULTIMODE) | E16: =STOCK!E14 -> 1 | F16: ='JIO MIN'!E15 -> 0 | G16: ='JIO MRN'!E15 -> 0 | H16: ='TEAM OUT'!E15 -> 0 | I16: ='TEAM IN'!E15 -> 0 | J16: =E16+F16-G16-H16+I16 -> 1 | K16: 1 | L16: =J16-K16 -> 0
A17: 14 | B17: JAIPUR | C17: CABLE CPRI | D17: CPRI CABLE 70 MTR - (MULTIMODE) | E17: =STOCK!E15 -> 0 | F17: ='JIO MIN'!E16 -> 0 | G17: ='JIO MRN'!E16 -> 0 | H17: ='TEAM OUT'!E16 -> 0 | I17: ='TEAM IN'!E16 -> 0 | J17: =E17+F17-G17-H17+I17 -> 0 | L17: =J17-K17 -> 0
A18: 15 | B18: JAIPUR | C18: CABLE CPRI | D18: FIBER,LC DUP PC-LC DUP APC,SM,3MTR | E18: =STOCK!E16 -> 0 | F18: ='JIO MIN'!E17 -> 0 | G18: ='JIO MRN'!E17 -> 0 | H18: ='TEAM OUT'!E17 -> 0 | I18: ='TEAM IN'!E17 -> 0 | J18: =E18+F18-G18-H18+I18 -> 0 | L18: =J18-K18 -> 0
A19: 16 | B19: JAIPUR | C19: CABLE EARTHING | D19: EARTHING CABLE | E19: =STOCK!E17 -> 0 | F19: ='JIO MIN'!E18 -> 0 | G19: ='JIO MRN'!E18 -> 0 | H19: ='TEAM OUT'!E18 -> 0 | I19: ='TEAM IN'!E18 -> 0 | J19: =E19+F19-G19-H19+I19 -> 0 | L19: =J19-K19 -> 0
A20: 17 | B20: JAIPUR | C20: CABLE POWER | D20: POWER CABLE 30 MTR (MULTIMODE) | E20: =STOCK!E18 -> 0 | F20: ='JIO MIN'!E19 -> 0 | G20: ='JIO MRN'!E19 -> 0 | H20: ='TEAM OUT'!E19 -> 0 | I20: ='TEAM IN'!E19 -> 0 | J20: =E20+F20-G20-H20+I20 -> 0 | L20: =J20-K20 -> 0
A21: 18 | B21: JAIPUR | C21: CABLE POWER | D21: POWER CABLE 40 MTR (MULTIMODE) | E21: =STOCK!E19 -> 0 | F21: ='JIO MIN'!E20 -> 0 | G21: ='JIO MRN'!E20 -> 0 | H21: ='TEAM OUT'!E20 -> 0 | I21: ='TEAM IN'!E20 -> 0 | J21: =E21+F21-G21-H21+I21 -> 0 | L21: =J21-K21 -> 0
A22: 19 | B22: JAIPUR | C22: CABLE POWER | D22: POWER CABLE 50 MTR (MULTIMODE) | E22: =STOCK!E20 -> 2 | F22: ='JIO MIN'!E21 -> 7 | G22: ='JIO MRN'!E21 -> 0 | H22: ='TEAM OUT'!E21 -> 0 | I22: ='TEAM IN'!E21 -> 0 | J22: =E22+F22-G22-H22+I22 -> 9 | K22: 9 | L22: =J22-K22 -> 0
A23: 20 | B23: JAIPUR | C23: CABLE POWER | D23: POWER CABLE 60 MTR (MULTIMODE) | E23: =STOCK!E21 -> 0 | F23: ='JIO MIN'!E22 -> 3 | G23: ='JIO MRN'!E22 -> 0 | H23: ='TEAM OUT'!E22 -> 0 | I23: ='TEAM IN'!E22 -> 0 | J23: =E23+F23-G23-H23+I23 -> 3 | K23: 3 | L23: =J23-K23 -> 0
A24: 21 | B24: JAIPUR | C24: CABLE POWER | D24: POWER CABLE 70 MTR (MULTIMODE) | E24: =STOCK!E22 -> 0 | F24: ='JIO MIN'!E23 -> 0 | G24: ='JIO MRN'!E23 -> 0 | H24: ='TEAM OUT'!E23 -> 0 | I24: ='TEAM IN'!E23 -> 0 | J24: =E24+F24-G24-H24+I24 -> 0 | L24: =J24-K24 -> 0
A25: 22 | B25: JAIPUR | C25: CLAMP | D25: EARTHING CLAMP | E25: =STOCK!E23 -> 0 | F25: ='JIO MIN'!E24 -> 1 | G25: ='JIO MRN'!E24 -> 0 | H25: ='TEAM OUT'!E24 -> 0 | I25: ='TEAM IN'!E24 -> 0 | J25: =E25+F25-G25-H25+I25 -> 1 | K25: 1 | L25: =J25-K25 -> 0
A26: 23 | B26: JAIPUR | C26: CLAMP | D26: GRIPPING CLAMP-STUB | E26: =STOCK!E24 -> 0 | F26: ='JIO MIN'!E25 -> 0 | G26: ='JIO MRN'!E25 -> 0 | H26: ='TEAM OUT'!E25 -> 0 | I26: ='TEAM IN'!E25 -> 0 | J26: =E26+F26-G26-H26+I26 -> 0 | L26: =J26-K26 -> 0
A27: 24 | B27: JAIPUR | C27: GLAND | D27: GLAND FREED FROM CPRI | E27: =STOCK!E25 -> 0 | F27: ='JIO MIN'!E26 -> 0 | G27: ='JIO MRN'!E26 -> 0 | H27: ='TEAM OUT'!E26 -> 0 | I27: ='TEAM IN'!E26 -> 0 | J27: =E27+F27-G27-H27+I27 -> 0 | L27: =J27-K27 -> 0
A28: 25 | B28: JAIPUR | C28: IRM KIT | D28: B6-INSTALLATION IRM KIT | E28: =STOCK!E26 -> 0 | F28: ='JIO MIN'!E27 -> 2 | G28: ='JIO MRN'!E27 -> 0 | H28: ='TEAM OUT'!E27 -> 0 | I28: ='TEAM IN'!E27 -> 0 | J28: =E28+F28-G28-H28+I28 -> 2 | K28: 2 | L28: =J28-K28 -> 0
A29: 26 | B29: JAIPUR | C29: IRM KIT | D29: A6 INSTALLATION IRM KIT | E29: =STOCK!E27 -> 2 | F29: ='JIO MIN'!E28 -> 8 | G29: ='JIO MRN'!E28 -> 0 | H29: ='TEAM OUT'!E28 -> 0 | I29: ='TEAM IN'!E28 -> 0 | J29: =E29+F29-G29-H29+I29 -> 10 | K29: 10 | L29: =J29-K29 -> 0
A30: 27 | B30: JAIPUR | C30: MOUNT BRACKET | D30: B6-MOUNTING BRACKET | E30: =STOCK!E28 -> 0 | F30: ='JIO MIN'!E29 -> 2 | G30: ='JIO MRN'!E29 -> 0 | H30: ='TEAM OUT'!E29 -> 0 | I30: ='TEAM IN'!E29 -> 0 | J30: =E30+F30-G30-H30+I30 -> 2 | K30: 2 | L30: =J30-K30 -> 0
A31: 28 | B31: JAIPUR | C31: MOUNT BRACKET | D31: A6 MOUNTING BRACKET | E31: =STOCK!E29 -> 2 | F31: ='JIO MIN'!E30 -> 8 | G31: ='JIO MRN'!E30 -> 0 | H31: ='TEAM OUT'!E30 -> 0 | I31: ='TEAM IN'!E30 -> 0 | J31: =E31+F31-G31-H31+I31 -> 10 | K31: 10 | L31: =J31-K31 -> 0
A32: 29 | B32: JAIPUR | C32: POLE MOUNT | D32: A6 GBM POLE MOUNT 1.6M | E32: =STOCK!E30 -> 3 | F32: ='JIO MIN'!E31 -> 0 | G32: ='JIO MRN'!E31 -> 0 | H32: ='TEAM OUT'!E31 -> 0 | I32: ='TEAM IN'!E31 -> 0 | J32: =E32+F32-G32-H32+I32 -> 3 | K32: 3 | L32: =J32-K32 -> 0
A33: 30 | B33: JAIPUR | C33: SFP | D33: SFP 10 G/S OPTICAL ETHERNET 10G BASE SR MM | E33: =STOCK!E31 -> 0 | F33: ='JIO MIN'!E32 -> 0 | G33: ='JIO MRN'!E32 -> 0 | H33: ='TEAM OUT'!E32 -> 0 | I33: ='TEAM IN'!E32 -> 0 | J33: =E33+F33-G33-H33+I33 -> 0 | L33: =J33-K33 -> 0
A34: 31 | B34: JAIPUR | C34: SFP | D34: SFP MULTIMODE 10G - AIR FIBER | E34: =STOCK!E32 -> 4 | F34: ='JIO MIN'!E33 -> 18 | G34: ='JIO MRN'!E33 -> 0 | H34: ='TEAM OUT'!E33 -> 0 | I34: ='TEAM IN'!E33 -> 0 | J34: =E34+F34-G34-H34+I34 -> 22 | K34: 22 | L34: =J34-K34 -> 0
A35: 32 | B35: JAIPUR | C35: SFP | D35: SFP MULTIMODE 1G - AIR FIBER | E35: =STOCK!E33 -> 0 | F35: ='JIO MIN'!E34 -> 0 | G35: ='JIO MRN'!E34 -> 0 | H35: ='TEAM OUT'!E34 -> 0 | I35: ='TEAM IN'!E34 -> 0 | J35: =E35+F35-G35-H35+I35 -> 0 | L35: =J35-K35 -> 0
A36: 33 | B36: JAIPUR | C36: ADAPTOR | D36: V1 TO V2 ADAPTER POWER CABLE | E36: =STOCK!E34 -> 0 | F36: ='JIO MIN'!E35 -> 0 | G36: ='JIO MRN'!E35 -> 0 | H36: ='TEAM OUT'!E35 -> 0 | I36: ='TEAM IN'!E35 -> 0 | J36: =E36+F36-G36-H36+I36 -> 0 | L36: =J36-K36 -> 0
A37: 34 | B37: JAIPUR | C37: ANTENNA | D37: ANTENNA 850 | E37: =STOCK!E35 -> 0 | F37: ='JIO MIN'!E36 -> 0 | G37: ='JIO MRN'!E36 -> 0 | H37: ='TEAM OUT'!E36 -> 0 | I37: ='TEAM IN'!E36 -> 0 | J37: =E37+F37-G37-H37+I37 -> 0 | K37: 0 | L37: =J37-K37 -> 0
A38: 35 | B38: JAIPUR | C38: ANTENNA | D38: ANTENNA PENTABAND | E38: =STOCK!E36 -> 0 | F38: ='JIO MIN'!E37 -> 8 | G38: ='JIO MRN'!E37 -> 0 | H38: ='TEAM OUT'!E37 -> 0 | I38: ='TEAM IN'!E37 -> 0 | J38: =E38+F38-G38-H38+I38 -> 8 | K38: 8 | L38: =J38-K38 -> 0
A39: 36 | B39: JAIPUR | C39: ANTENNA | D39: BI SECTOR ANTENNA - 2300 MHZ | E39: =STOCK!E37 -> 0 | F39: ='JIO MIN'!E38 -> 0 | G39: ='JIO MRN'!E38 -> 0 | H39: ='TEAM OUT'!E38 -> 0 | I39: ='TEAM IN'!E38 -> 0 | J39: =E39+F39-G39-H39+I39 -> 0 | K39: 0 | L39: =J39-K39 -> 0
A40: 37 | B40: JAIPUR | C40: ANTENNA | D40: MB ANTENNA PACKING BOX | E40: =STOCK!E38 -> 0 | F40: ='JIO MIN'!E39 -> 15 | G40: ='JIO MRN'!E39 -> 0 | H40: ='TEAM OUT'!E39 -> 0 | I40: ='TEAM IN'!E39 -> 0 | J40: =E40+F40-G40-H40+I40 -> 15 | K40: 15 | L40: =J40-K40 -> 0
...
